{"uuid": "367cfb23-9956-4371-a604-b8368f6f3cf1", "children": ["1b9b1b61-4553-43d1-b477-486f1454307d"], "befores": [{"name": "setup", "status": "broken", "statusDetails": {"message": "selenium.common.exceptions.WebDriverException: Message: 'chromedriver' executable needs to be in PATH. Please see https://sites.google.com/a/chromium.org/chromedriver/home\n\n", "trace": "  File \"/Library/Frameworks/Python.framework/Versions/3.8/lib/python3.8/site-packages/pluggy/callers.py\", line 187, in _multicall\n    res = hook_impl.function(*args)\n  File \"/Library/Frameworks/Python.framework/Versions/3.8/lib/python3.8/site-packages/_pytest/fixtures.py\", line 964, in pytest_fixture_setup\n    result = call_fixture_func(fixturefunc, request, kwargs)\n  File \"/Library/Frameworks/Python.framework/Versions/3.8/lib/python3.8/site-packages/_pytest/fixtures.py\", line 788, in call_fixture_func\n    res = next(it)\n  File \"/Users/soumyasen/PycharmProjects/SeleniumTest/tests/conftest.py\", line 15, in setup\n    driver = webdriver.Chrome(executable_path=\"../executables/chromedriver\")\n  File \"/Library/Frameworks/Python.framework/Versions/3.8/lib/python3.8/site-packages/selenium/webdriver/chrome/webdriver.py\", line 73, in __init__\n    self.service.start()\n  File \"/Library/Frameworks/Python.framework/Versions/3.8/lib/python3.8/site-packages/selenium/webdriver/common/service.py\", line 81, in start\n    raise WebDriverException(\n"}, "start": 1586330304012, "stop": 1586330304014}], "start": 1586330304012, "stop": 1586330304151}